Workbook

Sheet Calculator
A1: FXCM Simulation Calculator
A2: Blue cells are inputs - change them and every green result recalculates.
A4: 1 · INPUTS
A5: Product | B5: XAU/USD | C5: Any product, for your reference
A6: Order side | B6: Buy | C6: Buy profits when price goes up, Sell when it goes down
A7: Simulation direction | B7: Up | C7: Up = price hikes, Down = price drops (the Up / Down buttons)
A8: Start price | B8: 4520 | C8: Price the order is opened at (admin 'Start price')
A9: Amount to invest (margin budget) | B9: 1000 | C9: A number: how much money you put into the order
A10: Hike value | B10: 15 | C10: 15 = +15 % when Hike type is Percent, or +15 in currency when it is Currency
A11: Multiplier (leverage) | B11: 100 | C11: Order ticket 'Multiplier' (100 = 1:100)
A12: Units per lot | B12: 100 | C12: Platform rule: 1 lot = 100 units
A13: Handling fee rate | B13: 0.001 | C13: Platform rule: 0.1% of margin
A14: Max lots per order | B14: 100 | C14: Platform limit
A15: Min lot step | B15: 0.01 | C15: Platform minimum / step
A16: Hike type | B16: Percent | C16: Percent = % of the start price, Currency = a fixed amount added to / taken off the price
A17: 2 · WHAT TO TYPE INTO THE ADMIN SIMULATION
A18: Direction button | B18: =IF(B7="Up","↑ Up","↓ Down") | C18: Press this on the product's simulation controls
A19: Start price field | B19: =B8 | C19: Start price (optional) box
A20: Hike as percent | B20: =IF(B16="Percent",B10/100,B10/B8) | C20: Target price box, unit % (move away from the start price)
A21: Target as price | B21: =B8*(1+IF(B7="Up",1,-1)*B20) | C21: …or unit $ and type this price
A22: Hike as currency amount | B22: =ABS(B21-B8) | C22: Type this as the move when the unit is $
A24: 3 · HOW MANY LOTS TO BUY FOR YOUR AMOUNT
A25: Margin per 1 lot | B25: =B12*B8/B11 | C25: units × price ÷ multiplier
A26: Cost per 1 lot incl. fee | B26: =B25*(1+B13) | C26: margin + handling fee
A27: LOTS TO PURCHASE | B27: =MIN(B14,ROUNDDOWN(B9/B26/B15,0)*B15) | C27: Largest lot size your amount covers (rounded down to the lot step)
A28: Margin held | B28: =B27*B25
A29: Handling fee | B29: =B28*B13
A30: Total cash needed | B30: =B28+B29 | C30: must be ≤ your balance
A31: Left over from your amount | B31: =B9-B30
A33: 4 · RESULT WHEN THE TARGET IS REACHED
A34: Profit / loss (currency) | B34: =IF(B6="Buy",1,-1)*(B21-B8)*B27*B12 | C34: (target − start) × lots × units, sign by order side
A35: Return on margin (%) | B35: =IF(B28=0,0,B34/B28) | C35: profit ÷ margin held - what the account really earns
A36: Return on amount invested (%) | B36: =IF(B9=0,0,B34/B9) | C36: profit ÷ your amount, after fees: see next row
A37: Profit after fee (currency) | B37: =B34-B29
A38: Profit after fee (% of amount) | B38: =IF(B9=0,0,B37/B9)
A39: Balance after closing | B39: =B9+B37 | C39: your amount + profit after fee
A40: Move that wipes out the margin | B40: =IF(B27=0,0,B28/(B27*B12)) | C40: price move (currency) at which the margin is lost - the stop-out level is reached before this
A42: 5 · REVERSE: I WANT A PROFIT OF …
A43: Profit wanted (currency) | B43: 150 | C43: Type the profit you want in currency
A44: Lots needed | B44: =MIN(B14,ROUNDUP((B43+0)/(ABS(B21-B8)*B12)/B15,0)*B15) | C44: profit ÷ (price move × units), rounded up to the lot step
...

Sheet Scenarios
A1: Profit at different % moves (uses the lots from the Calculator sheet)
A3: Move % | B3: Target price | C3: Price change | D3: Profit (currency) | E3: Profit after fee | F3: Return on margin | G3: Return on amount
A4: 0.01 | B4: =Calculator!$B$8*(1+IF(Calculator!$B$7="Up",1,-1)*A4) | C4: =B4-Calculator!$B$8 | D4: =IF(Calculator!$B$6="Buy",1,-1)*C4*Calculator!$B$27*Calculator!$B$12 | E4: =D4-Calculator!$B$29 | F4: =IF(Calculator!$B$28=0,0,D4/Calculator!$B$28) | G4: =IF(Calculator!$B$9=0,0,E4/Calculator!$B$9)
A5: 0.02 | B5: =Calculator!$B$8*(1+IF(Calculator!$B$7="Up",1,-1)*A5) | C5: =B5-Calculator!$B$8 | D5: =IF(Calculator!$B$6="Buy",1,-1)*C5*Calculator!$B$27*Calculator!$B$12 | E5: =D5-Calculator!$B$29 | F5: =IF(Calculator!$B$28=0,0,D5/Calculator!$B$28) | G5: =IF(Calculator!$B$9=0,0,E5/Calculator!$B$9)
A6: 0.05 | B6: =Calculator!$B$8*(1+IF(Calculator!$B$7="Up",1,-1)*A6) | C6: =B6-Calculator!$B$8 | D6: =IF(Calculator!$B$6="Buy",1,-1)*C6*Calculator!$B$27*Calculator!$B$12 | E6: =D6-Calculator!$B$29 | F6: =IF(Calculator!$B$28=0,0,D6/Calculator!$B$28) | G6: =IF(Calculator!$B$9=0,0,E6/Calculator!$B$9)
A7: 0.1 | B7: =Calculator!$B$8*(1+IF(Calculator!$B$7="Up",1,-1)*A7) | C7: =B7-Calculator!$B$8 | D7: =IF(Calculator!$B$6="Buy",1,-1)*C7*Calculator!$B$27*Calculator!$B$12 | E7: =D7-Calculator!$B$29 | F7: =IF(Calculator!$B$28=0,0,D7/Calculator!$B$28) | G7: =IF(Calculator!$B$9=0,0,E7/Calculator!$B$9)
A8: 0.15 | B8: =Calculator!$B$8*(1+IF(Calculator!$B$7="Up",1,-1)*A8) | C8: =B8-Calculator!$B$8 | D8: =IF(Calculator!$B$6="Buy",1,-1)*C8*Calculator!$B$27*Calculator!$B$12 | E8: =D8-Calculator!$B$29 | F8: =IF(Calculator!$B$28=0,0,D8/Calculator!$B$28) | G8: =IF(Calculator!$B$9=0,0,E8/Calculator!$B$9)
A9: 0.2 | B9: =Calculator!$B$8*(1+IF(Calculator!$B$7="Up",1,-1)*A9) | C9: =B9-Calculator!$B$8 | D9: =IF(Calculator!$B$6="Buy",1,-1)*C9*Calculator!$B$27*Calculator!$B$12 | E9: =D9-Calculator!$B$29 | F9: =IF(Calculator!$B$28=0,0,D9/Calculator!$B$28) | G9: =IF(Calculator!$B$9=0,0,E9/Calculator!$B$9)
A10: 0.25 | B10: =Calculator!$B$8*(1+IF(Calculator!$B$7="Up",1,-1)*A10) | C10: =B10-Calculator!$B$8 | D10: =IF(Calculator!$B$6="Buy",1,-1)*C10*Calculator!$B$27*Calculator!$B$12 | E10: =D10-Calculator!$B$29 | F10: =IF(Calculator!$B$28=0,0,D10/Calculator!$B$28) | G10: =IF(Calculator!$B$9=0,0,E10/Calculator!$B$9)
A11: 0.3 | B11: =Calculator!$B$8*(1+IF(Calculator!$B$7="Up",1,-1)*A11) | C11: =B11-Calculator!$B$8 | D11: =IF(Calculator!$B$6="Buy",1,-1)*C11*Calculator!$B$27*Calculator!$B$12 | E11: =D11-Calculator!$B$29 | F11: =IF(Calculator!$B$28=0,0,D11/Calculator!$B$28) | G11: =IF(Calculator!$B$9=0,0,E11/Calculator!$B$9)
A12: 0.5 | B12: =Calculator!$B$8*(1+IF(Calculator!$B$7="Up",1,-1)*A12) | C12: =B12-Calculator!$B$8 | D12: =IF(Calculator!$B$6="Buy",1,-1)*C12*Calculator!$B$27*Calculator!$B$12 | E12: =D12-Calculator!$B$29 | F12: =IF(Calculator!$B$28=0,0,D12/Calculator!$B$28) | G12: =IF(Calculator!$B$9=0,0,E12/Calculator!$B$9)
A13: 1 | B13: =Calculator!$B$8*(1+IF(Calculator!$B$7="Up",1,-1)*A13) | C13: =B13-Calculator!$B$8 | D13: =IF(Calculator!$B$6="Buy",1,-1)*C13*Calculator!$B$27*Calculator!$B$12 | E13: =D13-Calculator!$B$29 | F13: =IF(Calculator!$B$28=0,0,D13/Calculator!$B$28) | G13: =IF(Calculator!$B$9=0,0,E13/Calculator!$B$9)
A15: Change the blue % values to test any move you like.

Sheet How it works
A1: Formulas (same as the trading platform)
A2: Margin held | B2: lots × units per lot × price ÷ multiplier
A3: Handling fee | B3: margin × 0.1%
A4: Profit / loss | B4: (exit price − entry price) × lots × units per lot (negative for a Sell if price rises)
A5: Lots for an amount | B5: amount ÷ (margin per lot × (1 + fee rate)), rounded DOWN to 0.01, max 100
A6: Lots for a profit | B6: profit ÷ (price move × units per lot), rounded UP to 0.01, max 100
A7: Target price | B7: start price × (1 ± move %) (+ for Up, − for Down)
A9: Using it with the admin simulation
A10: 1 | B10: Type your amount, start price, hike type (Percent or Currency) and hike value in the blue cells of the Calculator sheet.
A11: 2 | B11: On Admin → Products open the product, put the Start price in, choose Up/Down as shown in section 2.
A12: 3 | B12: Enter the Target as % (section 2) or as a price ($) and press Up/Down.
A13: 4 | B13: Place the order with the LOTS TO PURCHASE shown in section 3.
A15: Note | B15: The platform also applies a stop-out when margin level falls to 20%, so large leverage with a big adverse move can close the position before the margin is fully lost.
